<div class="chatlog__message-group">
  <div class="chatlog__author-avatar-container">
    <img class="chatlog__author-avatar" src="https://cdn.discordapp.com/avatars/293572563010060288/92f572b5e1ef6656a55498787c15a5ad.png?size=128" alt="Avatar" loading="lazy">
  </div>
  <div class="chatlog__messages">
    <span class="chatlog__author-name" title="tarunon#9603" data-user-id="293572563010060288" style="color: rgb(231,76,60)">tarunon</span>
    <span class="chatlog__timestamp">11-Jul-17 03:27 PM</span>
    <div class="chatlog__message " data-message-id="334354920906031106" id="message-334354920906031106" title="Message sent: 11-Jul-17 03:27 PM">
      <div class="chatlog__content">
        <div class="markdown">
          <span class="preserve-whitespace">↑確か、内側のcatchは内側doのtryのErrorを捕まえるはずだが、throwのErrorも捕まえてこの野郎！ってなった記憶がある</span>
          <span class="chatlog__edited-timestamp" title="11-Jul-17 03:28 PM">(edited)</span>
        </div>
      </div>
    </div>
    <div class="chatlog__message " data-message-id="334355104964542474" id="message-334355104964542474" title="Message sent: 11-Jul-17 03:27 PM">
      <div class="chatlog__content">
        <div class="markdown">
          <span class="preserve-whitespace">そもそもdo内でthrowしたものはcatchに行くのが正？</span>
        </div>
      </div>
    </div>
  </div>
</div>